Workbook
Name Slicer_created_date__Year1: #N/A

Sheet Subscription Cohort Data
A1: customer_id | B1: created_date | C1: canceled_date | D1: was_subscription_paid | E1: subscription_cost | F1: subscription_interval | G1: Cancellation Duration | H1: Subscription Weekday | J1: Subcrition Cancel in 1 Day | K1: Tatol no of cancelation of subcription | L1: Tatol no of cancelation of subcription without blank value | M1: Proprtion of 1 daycancel subcription
A2: 154536156 | B2: 44805 | D2: Yes | E2: 39 | F2: month | G2: =IF(C2="", "", DATEDIF(B2, C2, "D")) | H2: =TEXT(B2, "dddd") -> Thursday | J2: =COUNTIF(Table1[Cancellation Duration],1) -> 174 | K2: =COUNT(Table1[Cancellation Duration]) -> 2004 | L2: =COUNT(Table1[Cancellation Duration]) -COUNTBLANK(Table1[Cancellation Duration]) -> 939 | M2: =J2/K2 -> 0.086826347
A3: 149713408 | B3: 44805 | C3: 44806 | D3: No | E3: 39 | F3: month | G3: =IF(C3="", "", DATEDIF(B3, C3, "D")) -> 1 | H3: =TEXT(B3, "dddd") -> Thursday
A4: 153756284 | B4: 44805 | C4: 44806 | D4: No | E4: 39 | F4: month | G4: =IF(C4="", "", DATEDIF(B4, C4, "D")) -> 1 | H4: =TEXT(B4, "dddd") -> Thursday
A5: 121253113 | B5: 44805 | C5: 44827 | D5: Yes | E5: 39 | F5: month | G5: =IF(C5="", "", DATEDIF(B5, C5, "D")) -> 22 | H5: =TEXT(B5, "dddd") -> Thursday
A6: 154467210 | B6: 44805 | C6: 45106 | D6: Yes | E6: 39 | F6: month | G6: =IF(C6="", "", DATEDIF(B6, C6, "D")) -> 301 | H6: =TEXT(B6, "dddd") -> Thursday
A7: 154510811 | B7: 44805 | C7: 45054 | D7: Yes | E7: 39 | F7: month | G7: =IF(C7="", "", DATEDIF(B7, C7, "D")) -> 249 | H7: =TEXT(B7, "dddd") -> Thursday
A8: 154494346 | B8: 44805 | C8: 44891 | D8: Yes | E8: 39 | F8: month | G8: =IF(C8="", "", DATEDIF(B8, C8, "D")) -> 86 | H8: =TEXT(B8, "dddd") -> Thursday
A9: 148671505 | B9: 44805 | C9: 44888 | D9: Yes | E9: 39 | F9: month | G9: =IF(C9="", "", DATEDIF(B9, C9, "D")) -> 83 | H9: =TEXT(B9, "dddd") -> Thursday
A10: 154568379 | B10: 44805 | C10: 44859 | D10: Yes | E10: 39 | F10: month | G10: =IF(C10="", "", DATEDIF(B10, C10, "D")) -> 54 | H10: =TEXT(B10, "dddd") -> Thursday
A11: 154428434 | B11: 44805 | C11: 44865 | D11: Yes | E11: 39 | F11: month | G11: =IF(C11="", "", DATEDIF(B11, C11, "D")) -> 60 | H11: =TEXT(B11, "dddd") -> Thursday
A12: 154601651 | B12: 44805 | C12: 44830 | D12: Yes | E12: 39 | F12: month | G12: =IF(C12="", "", DATEDIF(B12, C12, "D")) -> 25 | H12: =TEXT(B12, "dddd") -> Thursday
A13: 122824692 | B13: 44805 | C13: 44819 | D13: Yes | E13: 39 | F13: month | G13: =IF(C13="", "", DATEDIF(B13, C13, "D")) -> 14 | H13: =TEXT(B13, "dddd") -> Thursday
A14: 152925600 | B14: 44806 | D14: Yes | E14: 39 | F14: month | G14: =IF(C14="", "", DATEDIF(B14, C14, "D")) | H14: =TEXT(B14, "dddd") -> Friday
A15: 151154171 | B15: 44806 | C15: 44806 | D15: Yes | E15: 39 | F15: month | G15: =IF(C15="", "", DATEDIF(B15, C15, "D")) -> 0 | H15: =TEXT(B15, "dddd") -> Friday
A16: 154640950 | B16: 44806 | C16: 44904 | D16: Yes | E16: 39 | F16: month | G16: =IF(C16="", "", DATEDIF(B16, C16, "D")) -> 98 | H16: =TEXT(B16, "dddd") -> Friday
A17: 154617329 | B17: 44806 | C17: 44861 | D17: Yes | E17: 39 | F17: month | G17: =IF(C17="", "", DATEDIF(B17, C17, "D")) -> 55 | H17: =TEXT(B17, "dddd") -> Friday
A18: 154089211 | B18: 44806 | C18: 44843 | D18: Yes | E18: 39 | F18: month | G18: =IF(C18="", "", DATEDIF(B18, C18, "D")) -> 37 | H18: =TEXT(B18, "dddd") -> Friday
A19: 154653820 | B19: 44806 | C19: 44830 | D19: Yes | E19: 39 | F19: month | G19: =IF(C19="", "", DATEDIF(B19, C19, "D")) -> 24 | H19: =TEXT(B19, "dddd") -> Friday
A20: 154131290 | B20: 44807 | D20: Yes | E20: 39 | F20: month | G20: =IF(C20="", "", DATEDIF(B20, C20, "D")) | H20: =TEXT(B20, "dddd") -> Saturday
A21: 154434009 | B21: 44807 | D21: Yes | E21: 39 | F21: month | G21: =IF(C21="", "", DATEDIF(B21, C21, "D")) | H21: =TEXT(B21, "dddd") -> Saturday
A22: 136108848 | B22: 44807 | C22: 44808 | D22: Yes | E22: 39 | F22: month | G22: =IF(C22="", "", DATEDIF(B22, C22, "D")) -> 1 | H22: =TEXT(B22, "dddd") -> Saturday
A23: 135185873 | B23: 44807 | C23: 45056 | D23: Yes | E23: 39 | F23: month | G23: =IF(C23="", "", DATEDIF(B23, C23, "D")) -> 249 | H23: =TEXT(B23, "dddd") -> Saturday
A24: 154592664 | B24: 44807 | C24: 45017 | D24: Yes | E24: 39 | F24: month | G24: =IF(C24="", "", DATEDIF(B24, C24, "D")) -> 210 | H24: =TEXT(B24, "dddd") -> Saturday
A25: 119436804 | B25: 44807 | C25: 45026 | D25: Yes | E25: 39 | F25: month | G25: =IF(C25="", "", DATEDIF(B25, C25, "D")) -> 219 | H25: =TEXT(B25, "dddd") -> Saturday
A26: 152929657 | B26: 44807 | C26: 44888 | D26: Yes | E26: 39 | F26: month | G26: =IF(C26="", "", DATEDIF(B26, C26, "D")) -> 81 | H26: =TEXT(B26, "dddd") -> Saturday
A27: 154708974 | B27: 44807 | C27: 44852 | D27: Yes | E27: 39 | F27: month | G27: =IF(C27="", "", DATEDIF(B27, C27, "D")) -> 45 | H27: =TEXT(B27, "dddd") -> Saturday
A28: 154567722 | B28: 44807 | C28: 44833 | D28: Yes | E28: 39 | F28: month | G28: =IF(C28="", "", DATEDIF(B28, C28, "D")) -> 26 | H28: =TEXT(B28, "dddd") -> Saturday
A29: 154719788 | B29: 44807 | C29: 44829 | D29: Yes | E29: 39 | F29: month | G29: =IF(C29="", "", DATEDIF(B29, C29, "D")) -> 22 | H29: =TEXT(B29, "dddd") -> Saturday
A30: 154809306 | B30: 44808 | C30: 44809 | D30: Yes | E30: 39 | F30: month | G30: =IF(C30="", "", DATEDIF(B30, C30, "D")) -> 1 | H30: =TEXT(B30, "dddd") -> Sunday
A31: 140391539 | B31: 44808 | C31: 45021 | D31: Yes | E31: 39 | F31: month | G31: =IF(C31="", "", DATEDIF(B31, C31, "D")) -> 213 | H31: =TEXT(B31, "dddd") -> Sunday
A32: 153194806 | B32: 44808 | C32: 45032 | D32: Yes | E32: 39 | F32: month | G32: =IF(C32="", "", DATEDIF(B32, C32, "D")) -> 224 | H32: =TEXT(B32, "dddd") -> Sunday
A33: 144402204 | B33: 44808 | C33: 44826 | D33: Yes | E33: 39 | F33: month | G33: =IF(C33="", "", DATEDIF(B33, C33, "D")) -> 18 | H33: =TEXT(B33, "dddd") -> Sunday
... A38: 153368891 | B38: 44808 | C38: 44845 | D38: Yes | E38: 39 | F38: month | G38: =IF(C38="", "", DATEDIF(B38, C38, "D")) -> 37 | H38: =TEXT(B38, "dddd") -> Sunday
A39: 154225450 | B39: 44809 | D39: Yes | E39: 39 | F39: month | G39: =IF(C39="", "", DATEDIF(B39, C39, "D")) | H39: =TEXT(B39, "dddd") -> Monday
A40: 154904040 | B40: 44809 | C40: 44810 | D40: Yes | E40: 39 | F40: month | G40: =IF(C40="", "", DATEDIF(B40, C40, "D")) -> 1 | H40: =TEXT(B40, "dddd") -> Monday
A41: 127604200 | B41: 44809 | C41: 44840 | D41: Yes | E41: 39 | F41: month | G41: =IF(C41="", "", DATEDIF(B41, C41, "D")) -> 31 | H41: =TEXT(B41, "dddd") -> Monday
A42: 154913576 | B42: 44809 | C42: 44998 | D42: Yes | E42: 39 | F42: month | G42: =IF(C42="", "", DATEDIF(B42, C42, "D")) -> 189 | H42: =TEXT(B42, "dddd") -> Monday
A43: 154910432 | B43: 44809 | C43: 44998 | D43: Yes | E43: 39 | F43: month | G43: =IF(C43="", "", DATEDIF(B43, C43, "D")) -> 189 | H43: =TEXT(B43, "dddd") -> Monday
A44: 154911229 | B44: 44809 | C44: 44997 | D44: Yes | E44: 39 | F44: month | G44: =IF(C44="", "", DATEDIF(B44, C44, "D")) -> 188 | H44: =TEXT(B44, "dddd") -> Monday
...

Sheet Data Description
B2: Field | C2: Description
A3: a | B3: customer_id | C3: Unique customer identification number representing an individual customer
A4: b | B4: created_date | C4: Date the customer subscription was created (DD/MM/YYYY).
A5: c | B5: canceled_date | C5: Date the customer subscription was canceled (DD/MM/YYYY). If value is blank then the subscription has not been canceled
A6: d | B6: subscription_cost | C6: Price of the subscription in USD
A7: e | B7: subscription_interval | C7: Measurement of time between billing occurrences for a recurring billing subscription
A8: f | B8: was_subscription_paid | C8: Indicates if payment was successfully collected for a subscription

Sheet Requirements
A32: Expected Dashboard

Sheet dashbord_feeder
A3: 1. Create a bar chart showing the number of new subscriptions per month for year 2022.
D8: Title | E8: Column Labels
D9: Number of new subcription in month | E9: 2022
D12: =_xlfn.TEXTJOIN(" ",TRUE,D9:G9) -> Number of new subcription in month 2022
B15: Row Labels | C15: Count of customer_id
B16: Sep | C16: 217
B17: Oct | C17: 196
B18: Nov | C18: 189
B19: Dec | C19: 230
B20: Grand Total | C20: 832
A25: 2. Make it Pie chart and Determine the percentage of paid vs. unpaid subscriptions.
B28: Row Labels | C28: Count of was_subscription_paid
B29: No | C29: 0.043336592
B30: Yes | C30: 0.95666341
B31: Grand Total | C31: 1
A35: 3 | B35: Subscription by Day Pivot Table
B37: Row Labels | C37: Count of customer_id
B38: Sunday | C38: 306
B39: Saturday | C39: 308
B40: Friday | C40: 452
B41: Thursday | C41: 505
B42: Wednesday | C42: 472
B43: Tuesday | C43: 487
B44: Monday | C44: 539
B45: Grand Total | C45: 3069
A51: 4 | B51: Subscrition over the time
B53: Row Labels | C53: Count of customer_id
C54: 1065
B55: 2022 | C55: 346
B56: 2023 | C56: 1658
B57: Grand Total | C57: 3069
A61: 5 | B61: Total no of suscription
B63: Row Labels | C63: Count of customer_id
B64: 2022 | C64: 832
B65: 2023 | C65: 2237
B66: Grand Total | C66: 3069
A71: 6 | B71: Total no of subscription cancel
B73: Count of canceled_date
B74: 2004
A79: 7 | B79: paid and unpiad subscription
...

Sheet Data_Analytics_Task
A3: Data Analysis Tasks:
A4: 1. Calculate the total number of subscriptions and cancellations.
B5: No. Of Subscriptions | D5: No. Of Cancellations
B6: =COUNTA('Subscription Cohort Data'!A2:A3070)-COUNTBLANK('Subscription Cohort Data'!A2:A3070) -> 3069 | D6: =COUNT('Subscription Cohort Data'!C2:C3070)-COUNTBLANK('Subscription Cohort Data'!C2:C3070) -> 939
A8: 2. Determine the percentage of paid vs. unpaid subscriptions.
B10: Paid Subscription | C10: Unpaid Subscription
B11: =COUNTIF(Table1[was_subscription_paid], "Yes") -> 2936 | C11: =COUNTIF(Table1[was_subscription_paid], "No") -> 133
B13: Paid Subscrition | C13: Unpaid Subscrition
B14: =B11/B6*100 -> 95.666341 | C14: =C11/B6*100 -> 4.3336592
A18: 3. Analyze the average subscription duration before cancellation.
B19: =AVERAGE(Table1[Cancellation Duration] ) -> 58.374251
A20: 4. Identify the date with the highest number of new subscriptions.
B22: Row Labels | C22: Count of created_date
B23: 44879 | C23: 20
B24: Grand Total | C24: 20
A27: 5. Find the proportion of subscriptions that were canceled within one day. | F27: ='Subscription Cohort Data'!J2/'Subscription Cohort Data'!K2 -> 0.086826347

Sheet Dashboard

Sheet Question_Analysis
A2: Questions for Analysis:
B4: 1. Which date had the highest number of subscriptions cancellations?
D6: Row Labels | E6: Count of canceled_date
D7: 45104 | E7: 14
D8: Grand Total | E8: 14
B10: 2. How many subscriptions were canceled on the same day they were created?
D13: {=MAX(_xlfn._xlws.FILTER(Table1[canceled_date], Table1[created_date]=Table1[canceled_date]))} -> 45172 | E13: =COUNTIF(Table1[canceled_date],D13) -> 10
B16: 3. What is the cancellation rate within the first two days of subscription? | F16: =COUNTIFS(Table1[Cancellation Duration], "<=2") / COUNTA(Table1[canceled_date]) -> 0.14620758
B18: 4. How many subscriptions lasted more than one month? | F18: =COUNTIFS(Table1[Cancellation Duration], ">30") -> 1267
B20: 5. What is the most common duration before cancellation?
D22: Subcrition Cancel in 1 Day | E22: =COUNTIF(Table1[Cancellation Duration],1) -> 174
B24: 6. How does the number of subscriptions vary by day?
C26: Row Labels | D26: Count of customer_id
C27: Monday | D27: 539
C28: Grand Total | D28: 539
B32: 7. Are there any indications that unpaid subscriptions have a higher cancellation rate?
C34: Data | D34: Value | F34: Paid Cancellation Rate | G34: Unpaid Cancellation Rate:
C35: Total Subscriptions | D35: =COUNTA('Subscription Cohort Data'!A2:A3070)-COUNTBLANK('Subscription Cohort Data'!A2:A3070) -> 3069 | F35: =D38/D37 -> 0.27792916 | G35: =D40/D39 -> 0.92481203
C36: Total Cancellations | D36: =COUNT('Subscription Cohort Data'!C2:C3070)-COUNTBLANK('Subscription Cohort Data'!C2:C3070) -> 939
C37: Paid Subscriptions | D37: =COUNTIF(Table1[was_subscription_paid], "Yes") -> 2936
C38: Paid Cancellations - Unpaid Cancellation → Because 939 - 133 = 806) | D38: =D36-D40 -> 816
C39: Unpaid Subscriptions | D39: =COUNTIF(Table1[was_subscription_paid], "No") -> 133
C40: Unpaid Cancellations | D40: =COUNTIFS('Subscription Cohort Data'!D2:D3070,"No",'Subscription Cohort Data'!C2:C3070,"<>") -> 123
C42: Yes, unpaid subscriptions clearly have a much higher cancellation rate (92%) compared to paid subscriptions (28%).
